{
 "cells": [
  {
   "cell_type": "code",
   "execution_count": null,
   "id": "0e8014a7",
   "metadata": {},
   "outputs": [
    {
     "ename": "RuntimeError",
     "evalue": "asyncio.run() cannot be called from a running event loop",
     "output_type": "error",
     "traceback": [
      "\u001b[31m---------------------------------------------------------------------------\u001b[39m",
      "\u001b[31mRuntimeError\u001b[39m                              Traceback (most recent call last)",
      "\u001b[36mCell\u001b[39m\u001b[36m \u001b[39m\u001b[32mIn[2]\u001b[39m\u001b[32m, line 14\u001b[39m\n\u001b[32m     11\u001b[39m         \u001b[38;5;28mprint\u001b[39m(result.markdown)\n\u001b[32m     13\u001b[39m \u001b[38;5;66;03m# Run the async main function\u001b[39;00m\n\u001b[32m---> \u001b[39m\u001b[32m14\u001b[39m \u001b[43masyncio\u001b[49m\u001b[43m.\u001b[49m\u001b[43mrun\u001b[49m\u001b[43m(\u001b[49m\u001b[43mmain\u001b[49m\u001b[43m(\u001b[49m\u001b[43m)\u001b[49m\u001b[43m)\u001b[49m\n",
      "\u001b[36mFile \u001b[39m\u001b[32m~/.python/current/lib/python3.12/asyncio/runners.py:190\u001b[39m, in \u001b[36mrun\u001b[39m\u001b[34m(main, debug, loop_factory)\u001b[39m\n\u001b[32m    161\u001b[39m \u001b[38;5;250m\u001b[39m\u001b[33;03m\"\"\"Execute the coroutine and return the result.\u001b[39;00m\n\u001b[32m    162\u001b[39m \n\u001b[32m    163\u001b[39m \u001b[33;03mThis function runs the passed coroutine, taking care of\u001b[39;00m\n\u001b[32m   (...)\u001b[39m\u001b[32m    186\u001b[39m \u001b[33;03m    asyncio.run(main())\u001b[39;00m\n\u001b[32m    187\u001b[39m \u001b[33;03m\"\"\"\u001b[39;00m\n\u001b[32m    188\u001b[39m \u001b[38;5;28;01mif\u001b[39;00m events._get_running_loop() \u001b[38;5;129;01mis\u001b[39;00m \u001b[38;5;129;01mnot\u001b[39;00m \u001b[38;5;28;01mNone\u001b[39;00m:\n\u001b[32m    189\u001b[39m     \u001b[38;5;66;03m# fail fast with short traceback\u001b[39;00m\n\u001b[32m--> \u001b[39m\u001b[32m190\u001b[39m     \u001b[38;5;28;01mraise\u001b[39;00m \u001b[38;5;167;01mRuntimeError\u001b[39;00m(\n\u001b[32m    191\u001b[39m         \u001b[33m\"\u001b[39m\u001b[33masyncio.run() cannot be called from a running event loop\u001b[39m\u001b[33m\"\u001b[39m)\n\u001b[32m    193\u001b[39m \u001b[38;5;28;01mwith\u001b[39;00m Runner(debug=debug, loop_factory=loop_factory) \u001b[38;5;28;01mas\u001b[39;00m runner:\n\u001b[32m    194\u001b[39m     \u001b[38;5;28;01mreturn\u001b[39;00m runner.run(main)\n",
      "\u001b[31mRuntimeError\u001b[39m: asyncio.run() cannot be called from a running event loop"
     ]
    }
   ],
   "source": []
  }
 ],
 "metadata": {
  "kernelspec": {
   "display_name": "Python 3",
   "language": "python",
   "name": "python3"
  },
  "language_info": {
   "codemirror_mode": {
    "name": "ipython",
    "version": 3
   },
   "file_extension": ".py",
   "mimetype": "text/x-python",
   "name": "python",
   "nbconvert_exporter": "python",
   "pygments_lexer": "ipython3",
   "version": "3.12.1"
  }
 },
 "nbformat": 4,
 "nbformat_minor": 5
}
